Workbook

Sheet Group Stage
B2: Gran Quinela Mundialista RMP / PEYITO
F3: Pago: | G3: 20 | H3: 0 | I3: 20 | J3: 20 | K3: 20 | L3: 20 | M3: 20 | N3: 20 | O3: 20 | P3: 20 | Q3: 20 | R3: 0 | S3: 0 | T3: 0 | U3: 0
B4: # | C4: Group | D4: Date | E4: Match | F4: Official Result | G4: Enrique | H4: Raul MP | I4: Fernando MP | J4: MATTHEW | K4: Karla Alonzo | L4: Milena | M4: Eduardo MP | N4: Miranda | O4: Juan Corredor | P4: Eddie y Liza | Q4: AX ML | R4: Ricardo JR | S4: Carito | T4: Peyito | U4: Eduardo Sama
B5: 1 | C5: Group A | D5: Jun 11 | E5: South Africa vs Mexico | F5: 2 | G5: 2 | H5: X | I5: X | J5: X | K5: 2 | L5: 2 | M5: 2 | N5: 2 | O5: 2 | P5: 2 | Q5: 2 | R5: 2 | S5: 2 | T5: 2 | U5: 2
B6: 2 | C6: Group A | D6: Jun 12 | E6: Czech Republic vs South Korea | G6: X | H6: 1 | I6: 1 | J6: 2 | K6: x | L6: X | M6: x | N6: 2 | O6: X | P6: X | Q6: X | R6: X | S6: 2 | T6: 1 | U6: x
B7: 3 | C7: Group A | D7: Jun 18 | E7: South Africa vs Czech Republic | G7: 2 | H7: 2 | I7: 1 | J7: 2 | K7: 2 | L7: 1 | M7: 2 | N7: 2 | O7: 2 | P7: 2 | Q7: 2 | R7: 2 | S7: 2 | T7: 2 | U7: 2
B8: 4 | C8: Group A | D8: Jun 19 | E8: South Korea vs Mexico | G8: X | H8: 1 | I8: 2 | J8: 2 | K8: x | L8: 2 | M8: 2 | N8: x | O8: 2 | P8: 2 | Q8: 2 | R8: 2 | S8: 2 | T8: 1 | U8: 2
B9: 5 | C9: Group A | D9: Jun 25 | E9: South Korea vs South Africa | G9: 1 | H9: 1 | I9: X | J9: 2 | K9: 1 | L9: 2 | M9: 1 | N9: 1 | O9: 1 | P9: 1 | Q9: 1 | R9: 1 | S9: 1 | T9: 1 | U9: 1
B10: 6 | C10: Group A | D10: Jun 25 | E10: Mexico vs Czech Republic | G10: 1 | H10: X | I10: 1 | J10: 2 | K10: 1 | L10: 1 | M10: 1 | N10: 1 | O10: 1 | P10: 1 | Q10: X | R10: X | S10: x | T10: x | U10: 1
B11: 7 | C11: Group B | D11: Jun 12 | E11: Bosnia-Herzegovina vs Canada | G11: X | H11: X | I11: 1 | J11: X | K11: x | L11: 2 | M11: x | N11: 2 | O11: 2 | P11: 2 | Q11: X | R11: 2 | S11: 2 | T11: x | U11: 2
B12: 8 | C12: Group B | D12: Jun 13 | E12: Switzerland vs Qatar | G12: X | H12: 1 | I12: X | J12: 2 | K12: 1 | L12: 1 | M12: 1 | N12: 1 | O12: 1 | P12: X | Q12: 1 | R12: 1 | S12: 1 | T12: 1 | U12: 1
B13: 9 | C13: Group B | D13: Jun 18 | E13: Bosnia-Herzegovina vs Switzerland | G13: X | H13: 2 | I13: 1 | J13: X | K13: 2 | L13: 2 | M13: x | N13: 2 | O13: 2 | P13: 2 | Q13: 2 | R13: 2 | S13: 2 | T13: 2 | U13: 2
B14: 10 | C14: Group B | D14: Jun 18 | E14: Qatar vs Canada | G14: 2 | H14: 2 | I14: X | J14: 2 | K14: 2 | L14: 2 | M14: 2 | N14: 2 | O14: 2 | P14: 2 | Q14: 2 | R14: 2 | S14: 1 | T14: 2 | U14: 2
B15: 11 | C15: Group B | D15: Jun 24 | E15: Canada vs Switzerland | G15: X | H15: 2 | I15: 2 | J15: 2 | K15: x | L15: 2 | M15: 2 | N15: 2 | O15: 1 | P15: 1 | Q15: 1 | R15: X | S15: 2 | T15: x | U15: x
B16: 12 | C16: Group B | D16: Jun 24 | E16: Qatar vs Bosnia-Herzegovina | G16: 1 | H16: X | I16: X | J16: X | K16: x | L16: X | M16: 2 | N16: x | O16: 1 | P16: 1 | Q16: X | R16: 2 | S16: x | T16: x | U16: 2
B17: 13 | C17: Group C | D17: Jun 13 | E17: Morocco vs Brazil | G17: X | H17: X | I17: 2 | J17: 2 | K17: x | L17: 2 | M17: 2 | N17: x | O17: 2 | P17: 2 | Q17: 2 | R17: 2 | S17: 2 | T17: x | U17: 2
B18: 14 | C18: Group C | D18: Jun 14 | E18: Scotland vs Haiti | G18: 1 | H18: 1 | I18: X | J18: 2 | K18: 1 | L18: 1 | M18: 1 | N18: 1 | O18: 1 | P18: 1 | Q18: 1 | R18: 1 | S18: 1 | T18: 1 | U18: 1
B19: 15 | C19: Group C | D19: Jun 19 | E19: Morocco vs Scotland | G19: 1 | H19: X | I19: 1 | J19: X | K19: 1 | L19: 2 | M19: x | N19: 1 | O19: 1 | P19: 1 | Q19: 1 | R19: 1 | S19: 2 | T19: 1 | U19: 1
B20: 16 | C20: Group C | D20: Jun 20 | E20: Haiti vs Brazil | G20: 2 | H20: 2 | I20: 2 | J20: 2 | K20: 2 | L20: 2 | M20: 2 | N20: 2 | O20: 2 | P20: 2 | Q20: 2 | R20: 2 | S20: 2 | T20: 2 | U20: 2
B21: 17 | C21: Group C | D21: Jun 24 | E21: Brazil vs Scotland | G21: 1 | H21: 1 | I21: 1 | J21: 2 | K21: 1 | L21: 1 | M21: 1 | N21: 1 | O21: 1 | P21: 1 | Q21: 1 | R21: 1 | S21: 1 | T21: 1 | U21: 1
B22: 18 | C22: Group C | D22: Jun 24 | E22: Haiti vs Morocco | G22: 2 | H22: 2 | I22: 1 | J22: 1 | K22: 2 | L22: X | M22: 2 | N22: 2 | O22: 2 | P22: 2 | Q22: 2 | R22: 2 | S22: 2 | T22: 2 | U22: 2
B23: 19 | C23: Group D | D23: Jun 13 | E23: Paraguay vs USA | G23: X | H23: X | I23: X | J23: 2 | K23: x | L23: 2 | M23: x | N23: x | O23: 1 | P23: 2 | Q23: X | R23: 2 | S23: 2 | T23: x | U23: 2
B24: 20 | C24: Group D | D24: Jun 14 | E24: Turkey vs Australia | G24: 1 | H24: 1 | I24: 1 | J24: 2 | K24: 1 | L24: 1 | M24: 1 | N24: x | O24: 2 | P24: 1 | Q24: 1 | R24: 1 | S24: 1 | T24: 1 | U24: 1
B25: 21 | C25: Group D | D25: Jun 19 | E25: Australia vs USA | G25: 2 | H25: 2 | I25: 2 | J25: 2 | K25: 2 | L25: X | M25: 2 | N25: 2 | O25: 2 | P25: X | Q25: 2 | R25: 2 | S25: 2 | T25: 2 | U25: 2
B26: 22 | C26: Group D | D26: Jun 20 | E26: Paraguay vs Turkey | G26: 2 | H26: 1 | I26: X | J26: 2 | K26: x | L26: 2 | M26: x | N26: 1 | O26: 1 | P26: 2 | Q26: X | R26: X | S26: 2 | T26: x | U26: 2
B27: 23 | C27: Group D | D27: Jun 26 | E27: USA vs Turkey | G27: 2 | H27: 2 | I27: X | J27: 2 | K27: 2 | L27: 1 | M27: x | N27: 1 | O27: 1 | P27: 2 | Q27: 2 | R27: X | S27: 2 | T27: 2 | U27: 1
B28: 24 | C28: Group D | D28: Jun 26 | E28: Australia vs Paraguay | G28: 2 | H28: 2 | I28: 2 | J28: X | K28: x | L28: 1 | M28: 2 | N28: 2 | O28: X | P28: 2 | Q28: 2 | R28: 2 | S28: 2 | T28: 2 | U28: x
B29: 25 | C29: Group E | D29: Jun 14 | E29: Germany vs Curaçao | G29: 1 | H29: 1 | I29: 1 | J29: 1 | K29: 1 | L29: 1 | M29: 1 | N29: 1 | O29: 1 | P29: 1 | Q29: 1 | R29: 1 | S29: 1 | T29: 1 | U29: 1
B30: 26 | C30: Group E | D30: Jun 14 | E30: Ecuador vs Ivory Coast | G30: 1 | H30: 1 | I30: 2 | J30: X | K30: x | L30: 1 | M30: 1 | N30: x | O30: 1 | P30: 2 | Q30: 1 | R30: X | S30: 1 | T30: 1 | U30: x
B31: 27 | C31: Group E | D31: Jun 20 | E31: Ivory Coast vs Germany | G31: X | H31: 2 | I31: X | J31: 2 | K31: 2 | L31: 2 | M31: 2 | N31: 2 | O31: 2 | P31: 2 | Q31: 2 | R31: 2 | S31: 2 | T31: 2 | U31: 2
B32: 28 | C32: Group E | D32: Jun 21 | E32: Curaçao vs Ecuador | G32: 2 | H32: 2 | I32: 2 | J32: X | K32: 2 | L32: 2 | M32: 2 | N32: 2 | O32: 2 | P32: X | Q32: 2 | R32: 2 | S32: 2 | T32: 2 | U32: 2
B33: 29 | C33: Group E | D33: Jun 25 | E33: Germany vs Ecuador | G33: 1 | H33: 1 | I33: 1 | J33: 2 | K33: 1 | L33: X | M33: x | N33: 1 | O33: 1 | P33: 1 | Q33: 1 | R33: X | S33: 1 | T33: 1 | U33: 1
B34: 30 | C34: Group E | D34: Jun 25 | E34: Ivory Coast vs Curaçao | G34: 1 | H34: 1 | I34: 1 | J34: 2 | K34: 1 | L34: 1 | M34: 1 | N34: 1 | O34: 1 | P34: 2 | Q34: 1 | R34: 1 | S34: x | T34: 1 | U34: 1
B35: 31 | C35: Group F | D35: Jun 14 | E35: Japan vs Netherlands | G35: 2 | H35: x | I35: X | J35: 2 | K35: x | L35: 2 | M35: 2 | N35: 1 | O35: X | P35: 2 | Q35: 2 | R35: X | S35: 2 | T35: x | U35: 2
B36: 32 | C36: Group F | D36: Jun 15 | E36: Tunisia vs Sweden | G36: X | H36: 2 | I36: 2 | J36: 2 | K36: x | L36: 2 | M36: x | N36: 2 | O36: 1 | P36: 2 | Q36: X | R36: X | S36: x | T36: x | U36: 2
B37: 33 | C37: Group F | D37: Jun 20 | E37: Sweden vs Netherlands | G37: 2 | H37: 2 | I37: X | J37: 2 | K37: 2 | L37: X | M37: 2 | N37: 2 | O37: 2 | P37: 2 | Q37: 2 | R37: 2 | S37: 2 | T37: 2 | U37: 2
B38: 34 | C38: Group F | D38: Jun 21 | E38: Japan vs Tunisia | G38: 1 | H38: 1 | I38: 1 | J38: 1 | K38: 1 | L38: 1 | M38: x | N38: 1 | O38: 1 | P38: 1 | Q38: 1 | R38: 1 | S38: 1 | T38: 1 | U38: 1
B39: 35 | C39: Group F | D39: Jun 25 | E39: Netherlands vs Tunisia | G39: 1 | H39: 1 | I39: 1 | J39: X | K39: 1 | L39: 1 | M39: 1 | N39: 1 | O39: 1 | P39: 1 | Q39: 1 | R39: 1 | S39: 1 | T39: 1 | U39: 1
B40: 36 | C40: Group F | D40: Jun 25 | E40: Sweden vs Japan | G40: 2 | H40: x | I40: X | J40: 2 | K40: x | L40: X | M40: 2 | N40: 2 | O40: 2 | P40: 2 | Q40: 2 | R40: X | S40: x | T40: x | U40: x
B41: 37 | C41: Group G | D41: Jun 15 | E41: Egypt vs Belgium | G41: 2 | H41: 2 | I41: 2 | J41: 1 | K41: 2 | L41: 2 | M41: 2 | N41: 2 | O41: 2 | P41: 2 | Q41: 2 | R41: 2 | S41: 2 | T41: 2 | U41: 2
...

Sheet Scoreboard
B2: LEADEBOARD
B3: 10 points per correct prediction • 72 matches • 720 points possible
B4: Pos. | C4: Participant | D4: Total Points | E4: Accuracy % | F4: Correct Picks
B5: 1 | C5: =+'Group Stage'!$U$4 -> Eduardo Sama | D5: {=SUMPRODUCT(('Group Stage'!F5:F76<>"")*('Group Stage'!U5:U76<>"")*('Group Stage'!F5:F76='Group Stage'!U5:U76))*10} -> 10 | E5: =D5/(COUNT('Group Stage'!$F$5:$F$76)*10) -> 1 | F5: =IFERROR(D5/10,0) -> 1
B6: 2 | C6: ='Group Stage'!$G$4 -> Enrique | D6: =SUMPRODUCT(('Group Stage'!F5:F76<>"")*('Group Stage'!G5:G76<>"")*('Group Stage'!F5:F76='Group Stage'!G5:G76))*10 -> 10 | E6: =D6/(COUNT('Group Stage'!$F$5:$F$76)*10) -> 1 | F6: =IFERROR(D6/10,0) -> 1
B7: 3 | C7: ='Group Stage'!$K$4 -> Karla Alonzo | D7: =SUMPRODUCT(('Group Stage'!F5:F76<>"")*('Group Stage'!K5:K76<>"")*('Group Stage'!F5:F76='Group Stage'!K5:K76))*10 -> 10 | E7: =D7/(COUNT('Group Stage'!$F$5:$F$76)*10) -> 1 | F7: =IFERROR(D7/10,0) -> 1
B8: 4 | C8: ='Group Stage'!$L$4 -> Milena | D8: =SUMPRODUCT(('Group Stage'!F5:F76<>"")*('Group Stage'!L5:L76<>"")*('Group Stage'!F5:F76='Group Stage'!L5:L76))*10 -> 10 | E8: =D8/(COUNT('Group Stage'!$F$5:$F$76)*10) -> 1 | F8: =IFERROR(D8/10,0) -> 1
B9: 5 | C9: ='Group Stage'!$M$4 -> Eduardo MP | D9: =SUMPRODUCT(('Group Stage'!F5:F76<>"")*('Group Stage'!M5:M76<>"")*('Group Stage'!F5:F76='Group Stage'!M5:M76))*10 -> 10 | E9: =D9/(COUNT('Group Stage'!$F$5:$F$76)*10) -> 1 | F9: =IFERROR(D9/10,0) -> 1
B10: 6 | C10: ='Group Stage'!$N$4 -> Miranda | D10: =SUMPRODUCT(('Group Stage'!F5:F76<>"")*('Group Stage'!N5:N76<>"")*('Group Stage'!F5:F76='Group Stage'!N5:N76))*10 -> 10 | E10: =D10/(COUNT('Group Stage'!$F$5:$F$76)*10) -> 1 | F10: =IFERROR(D10/10,0) -> 1
B11: 7 | C11: ='Group Stage'!$O$4 -> Juan Corredor | D11: =SUMPRODUCT(('Group Stage'!F5:F76<>"")*('Group Stage'!O5:O76<>"")*('Group Stage'!F5:F76='Group Stage'!O5:O76))*10 -> 10 | E11: =D11/(COUNT('Group Stage'!$F$5:$F$76)*10) -> 1 | F11: =IFERROR(D11/10,0) -> 1
B12: 8 | C12: ='Group Stage'!$P$4 -> Eddie y Liza | D12: =SUMPRODUCT(('Group Stage'!F5:F76<>"")*('Group Stage'!P5:P76<>"")*('Group Stage'!F5:F76='Group Stage'!P5:P76))*10 -> 10 | E12: =D12/(COUNT('Group Stage'!$F$5:$F$76)*10) -> 1 | F12: =IFERROR(D12/10,0) -> 1
B13: 9 | C13: ='Group Stage'!$Q$4 -> AX ML | D13: {=SUMPRODUCT(('Group Stage'!F5:F76<>"")*('Group Stage'!Q5:Q76<>"")*('Group Stage'!F5:F76='Group Stage'!Q5:Q76))*10} -> 10 | E13: =D13/(COUNT('Group Stage'!$F$5:$F$76)*10) -> 1 | F13: =IFERROR(D13/10,0) -> 1
B14: 10 | C14: ='Group Stage'!$R$4 -> Ricardo JR | D14: {=SUMPRODUCT(('Group Stage'!F5:F76<>"")*('Group Stage'!R5:R76<>"")*('Group Stage'!F5:F76='Group Stage'!R5:R76))*10} -> 10 | E14: =D14/(COUNT('Group Stage'!$F$5:$F$76)*10) -> 1 | F14: =IFERROR(D14/10,0) -> 1
B15: 11 | C15: ='Group Stage'!$S$4 -> Carito | D15: {=SUMPRODUCT(('Group Stage'!F5:F76<>"")*('Group Stage'!S5:S76<>"")*('Group Stage'!F5:F76='Group Stage'!S5:S76))*10} -> 10 | E15: =D15/(COUNT('Group Stage'!$F$5:$F$76)*10) -> 1 | F15: =IFERROR(D15/10,0) -> 1
B16: 12 | C16: ='Group Stage'!$T$4 -> Peyito | D16: {=SUMPRODUCT(('Group Stage'!F5:F76<>"")*('Group Stage'!T5:T76<>"")*('Group Stage'!F5:F76='Group Stage'!T5:T76))*10} -> 10 | E16: =D16/(COUNT('Group Stage'!$F$5:$F$76)*10) -> 1 | F16: =IFERROR(D16/10,0) -> 1
B17: 13 | C17: ='Group Stage'!$H$4 -> Raul MP | D17: =SUMPRODUCT(('Group Stage'!F5:F76<>"")*('Group Stage'!H5:H76<>"")*('Group Stage'!F5:F76='Group Stage'!H5:H76))*10 -> 0 | E17: =D17/(COUNT('Group Stage'!$F$5:$F$76)*10) -> 0 | F17: =IFERROR(D17/10,0) -> 0
B18: 14 | C18: ='Group Stage'!$I$4 -> Fernando MP | D18: =SUMPRODUCT(('Group Stage'!F5:F76<>"")*('Group Stage'!I5:I76<>"")*('Group Stage'!F5:F76='Group Stage'!I5:I76))*10 -> 0 | E18: =D18/(COUNT('Group Stage'!$F$5:$F$76)*10) -> 0 | F18: =IFERROR(D18/10,0) -> 0
B19: 15 | C19: ='Group Stage'!$J$4 -> MATTHEW | D19: =SUMPRODUCT(('Group Stage'!F5:F76<>"")*('Group Stage'!J5:J76<>"")*('Group Stage'!F5:F76='Group Stage'!J5:J76))*10 -> 0 | E19: =D19/(COUNT('Group Stage'!$F$5:$F$76)*10) -> 0 | F19: =IFERROR(D19/10,0) -> 0
C21: Maximum Possible | D21: 720 | E21: 1 | F21: 72
